2023-12-02 13:09:50,062 INFO    StreamThr :9709 [internal.py:wandb_internal():89] W&B internal server running at pid: 9709, started at: 2023-12-02 13:09:50.061491
2023-12-02 13:09:50,066 DEBUG   HandlerThread:9709 [handler.py:handle_request():146] handle_request: status
2023-12-02 13:09:50,080 INFO    WriterThread:9709 [datastore.py:open_for_write():85] open: /home/andrea/Thesis/baselines/SCRIMP/wandb/run-20231202_130950-f3yl3edd/run-f3yl3edd.wandb
2023-12-02 13:09:50,082 DEBUG   SenderThread:9709 [sender.py:send():380] send: header
2023-12-02 13:09:50,134 DEBUG   SenderThread:9709 [sender.py:send():380] send: run
2023-12-02 13:09:50,147 INFO    SenderThread:9709 [sender.py:_maybe_setup_resume():760] checking resume status for yutong/SCRIMP_evaluation/f3yl3edd
2023-12-02 13:09:50,950 ERROR   SenderThread:9709 [internal_api.py:execute():370] 403 response executing GraphQL.
2023-12-02 13:09:50,950 ERROR   SenderThread:9709 [internal_api.py:execute():371] {"errors":[{"message":"permission denied","path":["upsertBucket"],"extensions":{"code":"PERMISSION_ERROR"}}],"data":{"upsertBucket":null}}
2023-12-02 13:09:50,950 ERROR   SenderThread:9709 [sender.py:send_run():979] It appears that you do not have permission to access the requested resource. Please reach out to the project owner to grant you access. If you have the correct permissions, verify that there are no issues with your networking setup.(Error 403: Forbidden)
Traceback (most recent call last):
  File "/home/andrea/miniconda3/envs/SCRIMP-env/lib/python3.7/site-packages/wandb/sdk/lib/retry.py", line 131, in __call__
    result = self._call_fn(*args, **kwargs)
  File "/home/andrea/miniconda3/envs/SCRIMP-env/lib/python3.7/site-packages/wandb/sdk/internal/internal_api.py", line 366, in execute
    return self.client.execute(*args, **kwargs)  # type: ignore
  File "/home/andrea/miniconda3/envs/SCRIMP-env/lib/python3.7/site-packages/wandb/vendor/gql-0.2.0/wandb_gql/client.py", line 52, in execute
    result = self._get_result(document, *args, **kwargs)
  File "/home/andrea/miniconda3/envs/SCRIMP-env/lib/python3.7/site-packages/wandb/vendor/gql-0.2.0/wandb_gql/client.py", line 60, in _get_result
    return self.transport.execute(document, *args, **kwargs)
  File "/home/andrea/miniconda3/envs/SCRIMP-env/lib/python3.7/site-packages/wandb/sdk/lib/gql_request.py", line 59, in execute
    request.raise_for_status()
  File "/home/andrea/miniconda3/envs/SCRIMP-env/lib/python3.7/site-packages/requests/models.py", line 1021, in raise_for_status
    raise HTTPError(http_error_msg, response=self)
requests.exceptions.HTTPError: 403 Client Error: Forbidden for url: https://api.wandb.ai/graphql

During handling of the above exception, another exception occurred:

Traceback (most recent call last):
  File "/home/andrea/miniconda3/envs/SCRIMP-env/lib/python3.7/site-packages/wandb/sdk/internal/sender.py", line 977, in send_run
    self._init_run(run, config_value_dict)
  File "/home/andrea/miniconda3/envs/SCRIMP-env/lib/python3.7/site-packages/wandb/sdk/internal/sender.py", line 1029, in _init_run
    commit=run.git.commit or None,
  File "/home/andrea/miniconda3/envs/SCRIMP-env/lib/python3.7/site-packages/wandb/apis/normalize.py", line 73, in wrapper
    raise err
  File "/home/andrea/miniconda3/envs/SCRIMP-env/lib/python3.7/site-packages/wandb/apis/normalize.py", line 41, in wrapper
    return func(*args, **kwargs)
  File "/home/andrea/miniconda3/envs/SCRIMP-env/lib/python3.7/site-packages/wandb/sdk/internal/internal_api.py", line 2012, in upsert_run
    **kwargs,
  File "/home/andrea/miniconda3/envs/SCRIMP-env/lib/python3.7/site-packages/wandb/sdk/internal/internal_api.py", line 341, in gql
    **kwargs,
  File "/home/andrea/miniconda3/envs/SCRIMP-env/lib/python3.7/site-packages/wandb/sdk/lib/retry.py", line 147, in __call__
    retry_timedelta_triggered = check_retry_fn(e)
  File "/home/andrea/miniconda3/envs/SCRIMP-env/lib/python3.7/site-packages/wandb/util.py", line 965, in check_retry_fn
    return fallback_retry_fn(e)
  File "/home/andrea/miniconda3/envs/SCRIMP-env/lib/python3.7/site-packages/wandb/util.py", line 908, in no_retry_auth
    "It appears that you do not have permission to access the requested resource. "
wandb.errors.CommError: It appears that you do not have permission to access the requested resource. Please reach out to the project owner to grant you access. If you have the correct permissions, verify that there are no issues with your networking setup.(Error 403: Forbidden)
2023-12-02 13:09:51,183 DEBUG   HandlerThread:9709 [handler.py:handle_request():146] handle_request: shutdown
2023-12-02 13:09:51,184 INFO    HandlerThread:9709 [handler.py:finish():866] shutting down handler
2023-12-02 13:09:51,956 INFO    SenderThread:9709 [sender.py:finish():1536] shutting down sender
2023-12-02 13:09:52,134 INFO    WriterThread:9709 [datastore.py:close():294] close: /home/andrea/Thesis/baselines/SCRIMP/wandb/run-20231202_130950-f3yl3edd/run-f3yl3edd.wandb
